<mujoco model="iCub">
    <compiler angle="radian" meshdir="../../meshes/simmechanics/" />
    <size njmax="500" nconmax="100" />
    <asset>
        <mesh name="sim_sea_2-5_root_link_prt-binary" file="sim_sea_2-5_root_link_prt-binary.stl" scale="0.001 0.001 0.001" />
        <mesh name="sim_sea_2-5_r_hip_1_prt-binary" file="sim_sea_2-5_r_hip_1_prt-binary.stl" scale="0.001 0.001 0.001" />
        <mesh name="sim_sea_2-5_r_hip_2_prt-binary" file="sim_sea_2-5_r_hip_2_prt-binary.stl" scale="0.001 0.001 0.001" />
        <mesh name="sim_sea_2-5_r_upper_thigh_prt-binary" file="sim_sea_2-5_r_upper_thigh_prt-binary.stl" scale="0.001 0.001 0.001" />
        <mesh name="sim_sea_2-5_r_thigh_prt-binary" file="sim_sea_2-5_r_thigh_prt-binary.stl" scale="0.001 0.001 0.001" />
        <mesh name="sim_sea_2-5_r_shank_prt-binary" file="sim_sea_2-5_r_shank_prt-binary.stl" scale="0.001 0.001 0.001" />
        <mesh name="sim_sea_2-5_r_ankle_prt-binary" file="sim_sea_2-5_r_ankle_prt-binary.stl" scale="0.001 0.001 0.001" />
        <mesh name="sim_sea_2-5_r_foot_prt-binary" file="sim_sea_2-5_r_foot_prt-binary.stl" scale="0.001 0.001 0.001" />
        <mesh name="sim_sea_2-5_lap_belt_1_prt-binary" file="sim_sea_2-5_lap_belt_1_prt-binary.stl" scale="0.001 0.001 0.001" />
        <mesh name="sim_sea_2-5_lap_belt_2_prt-binary" file="sim_sea_2-5_lap_belt_2_prt-binary.stl" scale="0.001 0.001 0.001" />
        <mesh name="sim_sea_2-5_chest_bb_prt-binary" file="sim_sea_2-5_chest_bb_prt-binary.stl" scale="0.001 0.001 0.001" />
        <mesh name="sim_sea_2-5_neck_1_prt-binary" file="sim_sea_2-5_neck_1_prt-binary.stl" scale="0.001 0.001 0.001" />
        <mesh name="sim_sea_2-5_neck_2_prt-binary" file="sim_sea_2-5_neck_2_prt-binary.stl" scale="0.001 0.001 0.001" />
        <mesh name="sim_sea_2-5_head_prt-binary" file="sim_sea_2-5_head_prt-binary.stl" scale="0.001 0.001 0.001" />
        <mesh name="sim_sea_2-5_r_shoulder_1_prt-binary" file="sim_sea_2-5_r_shoulder_1_prt-binary.stl" scale="0.001 0.001 0.001" />
        <mesh name="sim_sea_2-5_r_shoulder_2_prt-binary" file="sim_sea_2-5_r_shoulder_2_prt-binary.stl" scale="0.001 0.001 0.001" />
        <mesh name="sim_sea_2-5_r_upper_arm_prt-binary" file="sim_sea_2-5_r_upper_arm_prt-binary.stl" scale="0.001 0.001 0.001" />
        <mesh name="sim_sea_2-5_r_elbow_prt-binary" file="sim_sea_2-5_r_elbow_prt-binary.stl" scale="0.001 0.001 0.001" />
        <mesh name="sim_sea_2-5_r_elbow_prosup_prt-binary" file="sim_sea_2-5_r_elbow_prosup_prt-binary.stl" scale="0.001 0.001 0.001" />
        <mesh name="sim_sea_2-5_r_forearm_prt-binary" file="sim_sea_2-5_r_forearm_prt-binary.stl" scale="0.001 0.001 0.001" />
        <mesh name="sim_sea_2-5_r_wrist_pitch_prt-binary" file="sim_sea_2-5_r_wrist_pitch_prt-binary.stl" scale="0.001 0.001 0.001" />
        <mesh name="sim_sea_2-5_r_hand_prt-binary" file="sim_sea_2-5_r_hand_prt-binary.stl" scale="0.001 0.001 0.001" />
        <mesh name="sim_sea_2-5_l_shoulder_1_prt-binary" file="sim_sea_2-5_l_shoulder_1_prt-binary.stl" scale="0.001 0.001 0.001" />
        <mesh name="sim_sea_2-5_l_shoulder_2_prt-binary" file="sim_sea_2-5_l_shoulder_2_prt-binary.stl" scale="0.001 0.001 0.001" />
        <mesh name="sim_sea_2-5_l_upper_arm_prt-binary" file="sim_sea_2-5_l_upper_arm_prt-binary.stl" scale="0.001 0.001 0.001" />
        <mesh name="sim_sea_2-5_l_elbow_prt-binary" file="sim_sea_2-5_l_elbow_prt-binary.stl" scale="0.001 0.001 0.001" />
        <mesh name="sim_sea_2-5_l_elbow_prosup_prt-binary" file="sim_sea_2-5_l_elbow_prosup_prt-binary.stl" scale="0.001 0.001 0.001" />
        <mesh name="sim_sea_2-5_l_forearm_prt-binary" file="sim_sea_2-5_l_forearm_prt-binary.stl" scale="0.001 0.001 0.001" />
        <mesh name="sim_sea_2-5_l_wrist_pitch_prt-binary" file="sim_sea_2-5_l_wrist_pitch_prt-binary.stl" scale="0.001 0.001 0.001" />
        <mesh name="sim_sea_2-5_l_hand_prt-binary" file="sim_sea_2-5_l_hand_prt-binary.stl" scale="0.001 0.001 0.001" />
        <mesh name="sim_sea_2-5_l_hip_1_prt-binary" file="sim_sea_2-5_l_hip_1_prt-binary.stl" scale="0.001 0.001 0.001" />
        <mesh name="sim_sea_2-5_l_hip_2_prt-binary" file="sim_sea_2-5_l_hip_2_prt-binary.stl" scale="0.001 0.001 0.001" />
        <mesh name="sim_sea_2-5_l_upper_thigh_prt-binary" file="sim_sea_2-5_l_upper_thigh_prt-binary.stl" scale="0.001 0.001 0.001" />
        <mesh name="sim_sea_2-5_l_thigh_prt-binary" file="sim_sea_2-5_l_thigh_prt-binary.stl" scale="0.001 0.001 0.001" />
        <mesh name="sim_sea_2-5_l_shank_prt-binary" file="sim_sea_2-5_l_shank_prt-binary.stl" scale="0.001 0.001 0.001" />
        <mesh name="sim_sea_2-5_l_ankle_prt-binary" file="sim_sea_2-5_l_ankle_prt-binary.stl" scale="0.001 0.001 0.001" />
        <mesh name="sim_sea_2-5_l_foot_prt-binary" file="sim_sea_2-5_l_foot_prt-binary.stl" scale="0.001 0.001 0.001" />
    </asset>
    <worldbody>
      <geom pos="-0.0364 0 0.032" quat="0.5 0.5 -0.5 -0.5" type="mesh" rgba="0 1 0 1" mesh="sim_sea_2-5_root_link_prt-binary" friction = "5 0.005 0.0001"/>

      <body name="torso_1" pos="0 0.0270463 0" quat="0.5 0.5 -0.5 -0.5">
            <inertial pos="0.0270921 0.029148 -0.0004398" quat="0.99901 0.0379433 0.00514218 -0.0226347" mass="0.67144" diaginertia="0.000409169 0.000384587 0.00029894" />
            <joint name="torso_pitch" pos="0 0 0" axis="1 0 0" limited="true" range="-0.349066 1.22173" damping="30.0" ref="0.0"/>
            <geom pos="0.0270463 0.032 0.0364" type="mesh" rgba="0 0 0.8 1" mesh="sim_sea_2-5_lap_belt_1_prt-binary" friction = "5 0.005 0.0001"/>

            <body name="torso_2" pos="0.0270463 0.032 -0.0573446">
                <inertial pos="-0.000113508 0.0361525 0.0570963" quat="0.706739 0.707474 -0.000124378 0.000167074" mass="0.425685" diaginertia="0.000829234 0.000604802 0.000436517" />
                <joint name="torso_roll" pos="0 0 0" axis="0 0 -1" limited="true" range="-0.523599 0.523599" damping="1.0" />
                <geom pos="0 0.1433 0.0386531" type="mesh" rgba="0.1 0.8 0.1 1" mesh="sim_sea_2-5_lap_belt_2_prt-binary" friction = "5 0.005 0.0001"/>

                <body name="chest" pos="0 0.05 0.0628421">
                    <inertial pos="0.000188619 0.073091 -0.0472381" quat="0.715214 -0.0122675 0.00447107 0.698784" mass="7.638" diaginertia="0.0440944 0.0430339 0.0260442" />
                    <joint name="torso_yaw" pos="0 0 0" axis="0 -1 0" limited="true" range="-0.872665 0.872665" damping="5.0" />
                    <geom pos="0 0.0928 -0.024189" type="mesh" mesh="sim_sea_2-5_chest_bb_prt-binary" friction = "5 0.005 0.0001" />


                    <body name="r_shoulder_1" pos="-0.120016 0.0928 0.0079693" quat="0 0.258819 0 0.965926">
                        <inertial pos="-0.0122656 3.2e-05 -0.00321064" quat="0.923843 -0.00544289 0.382668 0.00707733" mass="0.114862" diaginertia="0.0100036 0.01 0.00999644" />
                        <joint name="r_shoulder_pitch" pos="0 0 0" axis="-0.965926 0 0.258819" limited="true" range="-1.66679 0.174533" damping="5.0"/>
                        <geom pos="0.0990079 0 -0.0265292" type="mesh" rgba="0 0 1 1" mesh="sim_sea_2-5_r_shoulder_1_prt-binary" friction = "1 0.005 0.0001"/>

                        <body name="r_shoulder_2" pos="-0.00758047 0 0.0142102" quat="0.707107 -0.183013 1.00849e-07 -0.683013">
                            <inertial pos="-0.0214142 0.000271725 -0.0194402" quat="-0.0271128 0.922305 0.0516326 0.382037" mass="0.238162" diaginertia="0.0100103 0.01 0.00998966" />
                            <joint name="r_shoulder_roll" pos="0 0 0" axis="-0.258819 0 -0.965926" limited="true" range="0 2.80649" damping="5.0" />
                            <geom pos="0.106588 2.31915e-07 -0.0407392" type="mesh" rgba="1 1 0 1" mesh="sim_sea_2-5_r_shoulder_2_prt-binary" friction = "1 0.005 0.0001"/>


                            <body name="r_shoulder_3" pos="-0.0253461 2.3275e-07 -0.00538765" quat="0.991445 -0.126079 -9.78946e-09 0.0337826">
                                <inertial pos="-0.0632158 8.27444e-05 0.0256137" quat="0.414102 0.578567 0.558885 0.425943" mass="1.10423" diaginertia="0.0114392 0.0113832 0.0104961" />
                                <joint name="r_shoulder_yaw" pos="0 0 0" axis="0.965926 0 -0.258819" limited="true" range="-0.645772 1.39626" damping="5.0" />
                                <geom pos="0.131934 0 -0.0353516" type="mesh" rgba="1 0 1 1" mesh="sim_sea_2-5_r_upper_arm_prt-binary" friction = "1 0.005 0.0001"/>
                                <geom pos="0.131934 0 -0.0353516" type="mesh" rgba="0 1 1 1" mesh="sim_sea_2-5_r_elbow_prt-binary" friction = "1 0.005 0.0001"/>


                                <body name="r_elbow_1" pos="-0.127457 -0.0224999 0.049681">
                                    <inertial pos="-0.00673913 0.0188019 -0.00465769" quat="0.889627 0.287374 0.352074 0.0449803" mass="0.267903" diaginertia="0.0100112 0.0100037 0.00998517" />
                                    <joint name="r_elbow" pos="0 0 0" axis="0 1 0" limited="true" range="0.261799 1.85005" damping="5.0" />
                                    <geom pos="0.25939 0.0224999 -0.0850326" type="mesh" rgba="0 1 0 1" mesh="sim_sea_2-5_r_elbow_prosup_prt-binary" friction = "1 0.005 0.0001"/>
                                    <body name="r_forearm" pos="-0.0384624 0.0224999 -0.00522317">
                                        <inertial pos="-0.0404391 -0.000328 0.00532733" quat="0.380022 0.595027 0.594184 0.385319" mass="0.6347" diaginertia="0.000672292 0.000601594 0.000322074" />
                                        <joint name="r_wrist_prosup" pos="0 0 0" axis="0.965926 0 -0.258819" limited="true" range="-1.0472 1.0472" damping="5.0" />
                                        <geom pos="0.296887 0 -0.0795506" type="mesh" rgba="1 1 1 1" mesh="sim_sea_2-5_r_forearm_prt-binary" friction = "1 0.005 0.0001"/>
                                        <body name="r_wrist_1" pos="-0.103505 7e-06 0.0251977">
                                            <inertial pos="0.000986102 -0.001176 0.00410133" quat="0.920531 -0.046124 0.381345 0.0712175" mass="0.0362615" diaginertia="0.010001 0.01 0.00999904" />
                                            <joint name="r_wrist_pitch" pos="0 0 0" axis="0.258819 0 0.965926" limited="true" range="-1.39626 0.436332" damping="5.0" />
                                            <geom pos="0.400392 -7e-06 -0.104748" type="mesh" rgba="0 0 0.8 1" mesh="sim_sea_2-5_r_wrist_pitch_prt-binary" friction = "1 0.005 0.0001"/>

                                            <body name="r_hand" pos="0.000634106 -0.0194999 0.00236652">
                                                <inertial pos="-0.0646682 0.0056002 0.0226813" quat="-0.112385 0.892031 0.231018 0.37186" mass="0.248289" diaginertia="0.0100407 0.010002 0.00995729" />
                                                <joint name="r_wrist_yaw" pos="0 0 0" axis="0 1 0" limited="true" range="-0.349066 0.436332" damping="5.0" />
                                                <geom pos="0.399758 0.0194929 -0.107115" type="mesh" rgba="0.1 0.8 0.1 1" mesh="sim_sea_2-5_r_hand_prt-binary" friction = "1 0.005 0.0001"/>
                                            </body> <!-- right hand -->

                                        </body> <!-- right wrist 1 -->
                                    </body> <!-- right forearm -->
                                </body> <!-- right elbow 1 -->

                            </body> <!-- right shoulder 3 -->
                        </body> <!-- right shoulder 2 -->
                    </body> <!-- right shoulder 1 -->

                    <body name="l_shoulder_1" pos="0.120016 0.0928 0.0079693">
                        <inertial pos="-0.008985 -3.3e-05 -0.0088998" quat="-0.00583024 0.923837 0.00758142 0.382666" mass="0.114882" diaginertia="0.0100036 0.01 0.00999644" />
                        <joint name="l_shoulder_pitch" pos="0 0 0" axis="0.965926 0 0.258819" limited="true" range="-1.66679 0.174533" damping="5.0" />
                        <geom pos="-0.120257 0 -0.032223" type="mesh" mesh="sim_sea_2-5_l_shoulder_1_prt-binary" friction = "1 0.005 0.0001"/>

                        <body name="l_shoulder_2" pos="-0.013671 0 0.0085204" quat="0.707107 0.183013 0 -0.683013">
                            <inertial pos="0.0214746 0.000268958 -0.0194107" quat="0.922885 0.021839 0.382274 -0.0409079" mass="0.238162" diaginertia="0.010013 0.01 0.00998696" />
                            <joint name="l_shoulder_roll" pos="0 0 0" axis="-0.258819 0 0.965926" limited="true" range="0 2.80649" damping="5.0" />
                            <geom pos="-0.106587 1.10801e-07 -0.0407434" type="mesh" rgba="0 1 0 1" mesh="sim_sea_2-5_l_shoulder_2_prt-binary" friction = "1 0.005 0.0001"/>

                            <body name="l_shoulder_3" pos="0.0253143 1.11636e-07 -0.00540062" quat="0.991445 -0.126079 9.78946e-09 -0.0337826">
                                <inertial pos="0.0633194 0.00012243 0.025614" quat="0.550833 0.431858 0.40853 0.585819" mass="1.10593" diaginertia="0.0114438 0.0113869 0.0104966" />
                                <joint name="l_shoulder_yaw" pos="0 0 0" axis="0.965926 0 0.258819" limited="true" range="-0.645772 1.39626" damping="5.0" />
                                <geom pos="-0.131901 0 -0.0353428" type="mesh" rgba="0 0 0 1" mesh="sim_sea_2-5_l_upper_arm_prt-binary" friction = "1 0.005 0.0001"/>
                                <geom pos="-0.131901 0 -0.0353428" type="mesh" rgba="1 0 0 1" mesh="sim_sea_2-5_l_elbow_prt-binary" friction = "1 0.005 0.0001"/>

                                <body name="l_elbow_1" pos="0.127489 -0.0339999 0.0496898">
                                    <inertial pos="0.00673913 0.0303019 -0.00465769" quat="-0.287465 0.889618 -0.0449192 0.35203" mass="0.267903" diaginertia="0.0100112 0.0100037 0.00998517" />
                                    <joint name="l_elbow" pos="0 0 0" axis="0 -1 0" limited="true" range="0.261799 1.85005" damping="5.0" />
                                    <geom pos="-0.25939 0.0339999 -0.0850326" type="mesh" rgba="0 0 1 1" mesh="sim_sea_2-5_l_elbow_prosup_prt-binary" friction="1 0.005 0.0001"/>

                                    <body name="l_forearm" pos="0.0384624 0.0339999 -0.00522317">
                                        <inertial pos="0.0404512 -0.000686 0.00532363" quat="0.589221 0.393032 0.373008 0.599341" mass="0.636185" diaginertia="0.000674371 0.000605037 0.000323383" />
                                        <joint name="l_wrist_prosup" pos="0 0 0" axis="0.965926 0 0.258819" limited="true" range="-1.0472 1.0472" damping="5.0" />
                                        <geom pos="-0.296887 0 -0.0795506" type="mesh" rgba="1 1 0 1" mesh="sim_sea_2-5_l_forearm_prt-binary" friction="1 0.005 0.0001"/>

                                        <body name="l_wrist_1" pos="0.103428 7e-06 0.0254875">
                                            <inertial pos="-0.000981314 -0.001178 0.00408346" quat="0.0459991 0.920546 -0.0710737 0.381351" mass="0.0362152" diaginertia="0.010001 0.01 0.00999904" />
                                            <joint name="l_wrist_pitch" pos="0 0 0" axis="0.258819 0 -0.965926" limited="true" range="-1.39626 0.436332" damping="5.0" />
                                            <geom pos="-0.400315 -7e-06 -0.105038" type="mesh" rgba="1 0 1 1" mesh="sim_sea_2-5_l_wrist_pitch_prt-binary" friction="1 0.005 0.0001"/>


                                            <body name="l_hand" pos="-0.000634106 -0.0194999 0.00236652">
                                                <inertial pos="0.064768 0.0056304 0.0226602" quat="0.893006 0.114436 0.372673 -0.224856" mass="0.247806" diaginertia="0.0100411 0.0100025 0.00995639" />
                                                <joint name="l_wrist_yaw" pos="0 0 0" axis="0 1 0" limited="true" range="-0.349066 0.436332" damping="5.0" />
                                                <geom pos="-0.39968 0.0194929 -0.107405" type="mesh" rgba="0 1 1 1" mesh="sim_sea_2-5_l_hand_prt-binary" friction="1 0.005 0.0001"/>
                                            </body> <!-- left hand -->

                                        </body> <!-- left wrist 1 -->
                                    </body> <!-- left forearm  -->
                                </body> <!-- left elbow 1 -->

                            </body> <!-- left shoulder 3 -->
                        </body> <!-- left shoulder 2 -->
                    </body> <!-- left shoulder 1 -->

                    <body name="neck_1" pos="-0.0143 0.172797 0.0053118">
                        <inertial pos="0.0143706 0.006567 -0.0063842" quat="0.653136 0.273947 -0.267243 0.653412" mass="0.125793" diaginertia="0.0100094 0.01 0.0099906" />
                        <joint name="neck_pitch" pos="0 0 0" axis="-1 0 0" limited="true" range="-0.698132 0.383972" damping="5.0" />
                        <geom pos="0.0143 -0.079997 -0.0295008" type="mesh" rgba="0 1 0 1" mesh="sim_sea_2-5_neck_1_prt-binary" friction="1.0 0.005 0.0001"/>

                        <body name="neck_2" pos="0.0143 0.0095 0.0208">
                            <inertial pos="-8.8573e-05 0.035225 -0.0195453" quat="0.661135 0.24664 -0.294213 0.644599" mass="0.177087" diaginertia="0.0100098 0.01 0.00999014" />
                            <joint name="neck_roll" pos="0 0 0" axis="0 0 1" limited="true" range="-0.349066 0.349066" damping="5.0" />
                            <geom pos="0 -0.089497 -0.0503008" type="mesh" rgba="0 0 0 1" mesh="sim_sea_2-5_neck_2_prt-binary" friction="1.0 0.005 0.0001"/>

                            <body name="head" pos="0 -0.022344 -0.0208">
                                <inertial pos="-0.000574158 0.113511 -0.0075392" quat="0.995846 0.0892117 -0.017528 -0.00506802" mass="1.50691" diaginertia="0.00680747 0.00640004 0.00472579" />
                                <joint name="neck_yaw" pos="0 0 0" axis="0 1 0" limited="true" range="-0.872665 0.872665" damping="5.0" />
                                <geom pos="0 -0.067153 -0.0295008" type="mesh" rgba="1 0 0 1" mesh="sim_sea_2-5_head_prt-binary" friction="1.0 0.005 0.0001"/>
                            </body> <!-- head -->

                        </body> <!-- neck roll -->
                    </body> <!-- neck pitch -->

                </body> <!-- chest -->

            </body> <!-- torso 2 -->
        </body> <!-- torso 1 -->
    </worldbody>

    <actuator>
       <position ctrllimited="false" joint="torso_pitch" kp="5000" name="torso_pitch"></position>
       <position ctrllimited="false" joint="torso_roll" kp="200" name="torso_roll"></position>
       <position ctrllimited="false" joint="torso_yaw" kp="200" name="torso_yaw"></position>
       <position ctrllimited="false" joint="r_shoulder_pitch" kp="100" name="r_shoulder_pitch"></position>
       <position ctrllimited="false" joint="r_shoulder_roll" kp="100" name="r_shoulder_roll"></position>
       <position ctrllimited="false" joint="r_shoulder_yaw" kp="100" name="r_shoulder_yaw"></position>
       <position ctrllimited="false" joint="r_elbow" kp="100" name="r_elbow"></position>
       <position ctrllimited="false" joint="r_wrist_prosup" kp="100" name="r_wrist_prosup"></position>
       <position ctrllimited="false" joint="r_wrist_pitch" kp="100" name="r_wrist_pitch"></position>
       <position ctrllimited="false" joint="r_wrist_yaw" kp="100" name="r_wrist_yaw"></position>
       <position ctrllimited="false" joint="l_shoulder_pitch" kp="100" name="l_shoulder_pitch"></position>
       <position ctrllimited="false" joint="l_shoulder_roll" kp="100" name="l_shoulder_roll"></position>
       <position ctrllimited="false" joint="l_shoulder_yaw" kp="100" name="l_shoulder_yaw"></position>
       <position ctrllimited="false" joint="l_elbow" kp="100" name="l_elbow"></position>
       <position ctrllimited="false" joint="l_wrist_prosup" kp="100" name="l_wrist_prosup"></position>
       <position ctrllimited="false" joint="l_wrist_pitch" kp="100" name="l_wrist_pitch"></position>
       <position ctrllimited="false" joint="l_wrist_yaw" kp="100" name="l_wrist_yaw"></position>
       <position ctrllimited="false" joint="neck_pitch" kp="200" name="neck_pitch"></position>
       <position ctrllimited="false" joint="neck_roll" kp="600" name="neck_roll"></position>
       <position ctrllimited="false" joint="neck_yaw" kp="100" name="neck_yaw"></position>
    </actuator>
</mujoco>
